<?xml version="1.0" ?>
<!-- =================================================================================== -->
<!-- |    This document was autogenerated by xacro from neor_mini.urdf.xacro           | -->
<!-- |    EDITING THIS FILE BY HAND IS NOT RECOMMENDED                                 | -->
<!-- =================================================================================== -->
<robot name="neor_mini">
  <link name="base_link">
    <!-- avoid root link inertia warnings, annotation -->
    <inertial>
      <origin rpy="0 0 0" xyz="0.030649671440691 -1.79069899872708E-05 0.0558717976709459"/>
      <mass value="1.72617713171385"/>
      <inertia ixx="0.0107311274569357" ixy="-3.24164649120244E-08" ixz="0.00169188715816868" iyy="0.0198871551919603" iyz="2.40252669081509E-07" izz="0.0269841937242323"/>
    </inertial>
    <visual>
      <origin rpy="0 0 0" xyz="0 0 0"/>
      <geometry>
        <mesh filename="file:///home/youngricky/graduation_project_ws/install/ackermancar_description/share/ackermancar_description/meshes/neor_mini/base_link.stl"/>
      </geometry>
      <material name="">
        <color rgba="0.250980392156863 0.250980392156863 0.250980392156863 1"/>
      </material>
    </visual>
    <collision>
      <origin rpy="0 0 0" xyz="0 0 0"/>
      <geometry>
        <mesh filename="file:///home/youngricky/graduation_project_ws/install/ackermancar_description/share/ackermancar_description/meshes/neor_mini/base_link.stl"/>
      </geometry>
    </collision>
  </link>
  <link name="base_footprint">
  </link>
  <joint name="base_footprint_joint" type="fixed">
    <origin rpy="0 0 0" xyz="0 0 0"/>
    <parent link="base_footprint"/>
    <child link="base_link"/>
    <axis xyz="0 0 0.01"/>
  </joint>
  <link name="left_rear_link">
    <inertial>
      <origin rpy="0 0 0" xyz="7.85229659072684E-11 -0.0196762547002777 4.85059770127805E-11"/>
      <mass value="0.29556182905038"/>
      <inertia ixx="0.000374087423652291" ixy="2.19336154342606E-13" ixz="-5.50404301757561E-12" iyy="0.000661017199375587" iyz="-5.10049385981967E-14" izz="0.000374087441459994"/>
    </inertial>
    <visual>
      <origin rpy="0 0 0" xyz="0 0 0"/>
      <geometry>
        <mesh filename="file:///home/youngricky/graduation_project_ws/install/ackermancar_description/share/ackermancar_description/meshes/neor_mini/left_rear_link.stl"/>
      </geometry>
      <material name="">
        <color rgba="0.792156862745098 0.819607843137255 0.933333333333333 1"/>
      </material>
    </visual>
    <collision>
      <origin rpy="0 0 0" xyz="0 0 0"/>
      <geometry>
        <mesh filename="file:///home/youngricky/graduation_project_ws/install/ackermancar_description/share/ackermancar_description/meshes/neor_mini/left_rear_link.stl"/>
      </geometry>
    </collision>
  </link>
  <joint name="left_rear_joint" type="continuous">
    <origin rpy="0 0 0" xyz="-0.181499999999595 0.228542434993694 0.0399999999991634"/>
    <parent link="base_link"/>
    <child link="left_rear_link"/>
    <axis xyz="0 1 0"/>
    <limit effort="4000" velocity="100"/>
  </joint>
  <link name="right_rear_link">
    <inertial>
      <origin rpy="0 0 0" xyz="7.8521189550429E-11 0.0196762545376323 3.35983463273237E-11"/>
      <mass value="0.295561829050389"/>
      <inertia ixx="0.000374087423652306" ixy="-2.1933774523493E-13" ixz="5.50404145624456E-12" iyy="0.000661017199375601" iyz="-5.10073974604221E-14" izz="0.000374087441459995"/>
    </inertial>
    <visual>
      <origin rpy="0 0 0" xyz="0 0 0"/>
      <geometry>
        <mesh filename="file:///home/youngricky/graduation_project_ws/install/ackermancar_description/share/ackermancar_description/meshes/neor_mini/right_rear_link.stl"/>
      </geometry>
      <material name="">
        <color rgba="0.792156862745098 0.819607843137255 0.933333333333333 1"/>
      </material>
    </visual>
    <collision>
      <origin rpy="0 0 0" xyz="0 0 0"/>
      <geometry>
        <mesh filename="file:///home/youngricky/graduation_project_ws/install/ackermancar_description/share/ackermancar_description/meshes/neor_mini/right_rear_link.stl"/>
      </geometry>
    </collision>
  </link>
  <joint name="right_rear_joint" type="continuous">
    <origin rpy="0 0 0" xyz="-0.181499999999595 -0.228542434994426 0.0399999999991584"/>
    <parent link="base_link"/>
    <child link="right_rear_link"/>
    <axis xyz="0 1 0"/>
    <limit effort="4000" velocity="100"/>
  </joint>
  <!-- In order to fit ackermann simulation plugins's request,amend the front steer link and it's joint -->
  <link name="front_steer_right_link">
    <inertial>
      <origin rpy="0 0 0" xyz="9.44636555644252E-08 -0.000295273745285485 -8.13046296954667E-11"/>
      <mass value="0.296315811300368"/>
      <inertia ixx="0.000374692013709393" ixy="-9.17172260383823E-08" ixz="-2.43187512356516E-12" iyy="0.000661029987747155" iyz="1.9736939507106E-13" izz="0.000374691963930348"/>
    </inertial>
    <visual>
      <geometry>
        <cylinder length="0.001" radius="0.005"/>
      </geometry>
      <origin rpy="0 0 0" xyz="0 0 0"/>
      <material name="">
        <color rgba="0.792156862745098 0.819607843137255 0.933333333333333 1"/>
      </material>
    </visual>
    <collision>
      <origin rpy="0 0 0" xyz="0 0 0"/>
      <geometry>
        <cylinder length="0.001" radius="0.005"/>
      </geometry>
    </collision>
  </link>
  <joint name="front_steer_right_joint" type="revolute">
    <origin rpy="0 0 0" xyz="0.17 -0.21 0.102"/>
    <parent link="base_link"/>
    <child link="front_steer_right_link"/>
    <axis xyz="0 0 1"/>
    <limit effort="4000" lower="-0.69" upper="0.69" velocity="100"/>
  </joint>
  <!-- ************************************************************************************* -->
  <link name="front_right_wheel_link">
    <inertial>
      <origin rpy="0 0 0" xyz="9.44636555644252E-08 -0.000295273745285485 -8.13046296954667E-11"/>
      <mass value="0.296315811300368"/>
      <inertia ixx="0.000374692013709393" ixy="-9.17172260383823E-08" ixz="-2.43187512356516E-12" iyy="0.000661029987747155" iyz="1.9736939507106E-13" izz="0.000374691963930348"/>
    </inertial>
    <visual>
      <origin rpy="0 0 0" xyz="0 0 0"/>
      <geometry>
        <mesh filename="file:///home/youngricky/graduation_project_ws/install/ackermancar_description/share/ackermancar_description/meshes/neor_mini/front_right_wheel_link.stl"/>
      </geometry>
      <material name="">
        <color rgba="0.792156862745098 0.819607843137255 0.933333333333333 1"/>
      </material>
    </visual>
    <collision>
      <origin rpy="0 0 0" xyz="0 0 0"/>
      <geometry>
        <mesh filename="file:///home/youngricky/graduation_project_ws/install/ackermancar_description/share/ackermancar_description/meshes/neor_mini/front_right_wheel_link.stl"/>
      </geometry>
    </collision>
  </link>
  <joint name="front_right_wheel_joint" type="continuous">
    <origin rpy="0 0 0" xyz="0 0 -0.06"/>
    <parent link="front_steer_right_link"/>
    <child link="front_right_wheel_link"/>
    <axis xyz="0 1 0"/>
  </joint>
  <!-- In order to fit ackermann simulation plugins's request,amend the front steer link and it's joint -->
  <link name="front_steer_left_link">
    <inertial>
      <origin rpy="0 0 0" xyz="9.44636555644252E-08 -0.000295273745285485 -8.13046296954667E-11"/>
      <mass value="0.296315811300368"/>
      <inertia ixx="0.000374692013709393" ixy="-9.17172260383823E-08" ixz="-2.43187512356516E-12" iyy="0.000661029987747155" iyz="1.9736939507106E-13" izz="0.000374691963930348"/>
    </inertial>
    <visual>
      <geometry>
        <cylinder length="0.001" radius="0.005"/>
      </geometry>
      <origin rpy="0 0 0" xyz="0 0 0"/>
    </visual>
    <collision>
      <origin rpy="0 0 0" xyz="0 0 0"/>
      <geometry>
        <cylinder length="0.001" radius="0.005"/>
      </geometry>
    </collision>
  </link>
  <joint name="front_steer_left_joint" type="revolute">
    <origin rpy="0 0 0" xyz="0.17 0.21 0.102"/>
    <parent link="base_link"/>
    <child link="front_steer_left_link"/>
    <axis xyz="0 0 1"/>
    <limit effort="4000" lower="-0.69" upper="0.69" velocity="100"/>
  </joint>
  <!-- ************************************************************************************* -->
  <link name="front_left_wheel_link">
    <inertial>
      <origin rpy="0 0 0" xyz="-3.99413835339146E-11 0.000295273997845347 1.08602016268833E-10"/>
      <mass value="0.296315811293944"/>
      <inertia ixx="0.00037469197851121" ixy="-1.84493877596723E-13" ixz="-9.50756757097929E-12" iyy="0.00066103001709398" iyz="-1.17866882205563E-13" izz="0.000374691969713977"/>
    </inertial>
    <visual>
      <origin rpy="0 0 0" xyz="0 0 0"/>
      <geometry>
        <mesh filename="file:///home/youngricky/graduation_project_ws/install/ackermancar_description/share/ackermancar_description/meshes/neor_mini/front_left_wheel_link.stl"/>
      </geometry>
      <material name="">
        <color rgba="0.792156862745098 0.819607843137255 0.933333333333333 1"/>
      </material>
    </visual>
    <collision>
      <origin rpy="0 0 0" xyz="0 0 0"/>
      <geometry>
        <mesh filename="file:///home/youngricky/graduation_project_ws/install/ackermancar_description/share/ackermancar_description/meshes/neor_mini/front_left_wheel_link.stl"/>
      </geometry>
    </collision>
  </link>
  <joint name="front_left_wheel_joint" type="continuous">
    <origin rpy="0 0 0" xyz="0 0 -0.06"/>
    <parent link="front_steer_left_link"/>
    <child link="front_left_wheel_link"/>
    <axis xyz="0 1 0"/>
  </joint>
  <!--  add lidar link -->
  <link name="lidar">
    <visual>
      <geometry>
        <cylinder length="0.04" radius="0.03"/>
      </geometry>
    </visual>
  </link>
  <joint name="2Dlidar_joints" type="fixed">
    <origin rpy="0.0 0.0 0.0" xyz="0.0 0.0 0.13"/>
    <parent link="base_link"/>
    <child link="lidar"/>
  </joint>
  <!--  add lidar link -->
  <link name="lidar2">
    <visual>
      <geometry>
        <cylinder length="0.03" radius="0.02"/>
      </geometry>
    </visual>
  </link>
  <joint name="2Dlidar_joints2" type="fixed">
    <origin rpy="0.0 0.0 0.0" xyz="0.03 0.0 0.112"/>
    <parent link="base_link"/>
    <child link="lidar2"/>
  </joint>
  <!--*********************************************************************-->
  <link name="camera_link">
    <visual>
      <geometry>
        <box size="0.01 0.06 0.017"/>
      </geometry>
    </visual>
  </link>
  <joint name="camera_joints" type="fixed">
    <origin rpy="0.0 0.0 0.0" xyz="0.12 0.0 0.12"/>
    <parent link="base_link"/>
    <child link="camera_link"/>
  </joint>
  <!--*********************************************************************-->
  <!--  add imu llink   -->
  <link name="imu_link">
    <visual>
      <geometry>
        <box size="0.015 0.015 0.007"/>
      </geometry>
    </visual>
  </link>
  <joint name="imu_joints" type="fixed">
    <origin rpy="0.0 0.0 0.0" xyz="-0.10 0.0 0.02"/>
    <parent link="base_link"/>
    <child link="imu_link"/>
  </joint>
  <!--*********************************************************************-->
  <!--add color for links -->
  <gazebo reference="base_link">
    <material>Gazebo/DarkGrey </material>
  </gazebo>
  <gazebo reference="front_steer_left_link">
    <material>Gazebo/Road</material>
  </gazebo>
  <gazebo reference="front_steer_right_link">
    <material>Gazebo/Road</material>
  </gazebo>
  <gazebo reference="front_left_wheel_link">
    <material>Gazebo/Road</material>
  </gazebo>
  <gazebo reference="front_right_wheel_link">
    <material>Gazebo/Road</material>
  </gazebo>
  <gazebo reference="left_rear_link">
    <material>Gazebo/Road</material>
  </gazebo>
  <gazebo reference="right_rear_link">
    <material>Gazebo/Road</material>
  </gazebo>
  <gazebo reference="lidar">
    <material>Gazebo/Black</material>
  </gazebo>
  <gazebo reference="lidar2">
    <material>Gazebo/GreyTransparent</material>
  </gazebo>
  <gazebo reference="camera_link">
    <material>Gazebo/Black</material>
  </gazebo>
  <gazebo reference="imu_link">
    <material>Gazebo/Black</material>
  </gazebo>
  <!--*********************************************************************-->
  <gazebo reference="lidar">
    <sensor name="lidar_scanner" type="ray">
      <always_on>true</always_on>
      <visualize>false</visualize>
      <update_rate>8</update_rate>
      <ray>
        <scan>
          <horizontal>
            <samples>360</samples>
            <resolution>1</resolution>
            <min_angle>-3.141592653589793</min_angle>
            <max_angle>3.141592653589793</max_angle>
          </horizontal>
        </scan>
        <range>
          <min>0.10</min>
          <max>15.0</max>
          <resolution>0.1</resolution>
        </range>
      </ray>
      <plugin filename="libgazebo_ros_ray_sensor.so" name="scan">
        <ros>
          <remapping>~/out:=scan</remapping>
        </ros>
        <laser_topic_name>scan</laser_topic_name>
        <output_type>sensor_msgs/LaserScan</output_type>
        <frame_name>lidar</frame_name>
      </plugin>
    </sensor>
  </gazebo>
  <gazebo>
    <plugin filename="libneor_mini_gazebo_plugin.so" name="neor_mini_gazebo_plugin">
    </plugin>
  </gazebo>
  <gazebo reference="imu_link">
    <material>Gazebo/Black</material>
    <sensor name="imu_sensor" type="imu">
      <plugin filename="libgazebo_ros_imu_sensor.so" name="imu_plugin">
        <ros>
          <remapping>~/out:=imu</remapping>
        </ros>
        <initial_orientation_as_reference>false</initial_orientation_as_reference>
      </plugin>
      <always_on>true</always_on>
      <update_rate>60</update_rate>
      <visualize>true</visualize>
      <imu>
        <angular_velocity>
          <x>
            <noise type="gaussian">
              <mean>0.0</mean>
              <stddev>2e-4</stddev>
              <bias_mean>0.0000075</bias_mean>
              <bias_stddev>0.0000008</bias_stddev>
            </noise>
          </x>
          <y>
            <noise type="gaussian">
              <mean>0.0</mean>
              <stddev>2e-4</stddev>
              <bias_mean>0.0000075</bias_mean>
              <bias_stddev>0.0000008</bias_stddev>
            </noise>
          </y>
          <z>
            <noise type="gaussian">
              <mean>0.0</mean>
              <stddev>2e-4</stddev>
              <bias_mean>0.0000075</bias_mean>
              <bias_stddev>0.0000008</bias_stddev>
            </noise>
          </z>
        </angular_velocity>
        <linear_acceleration>
          <x>
            <noise type="gaussian">
              <mean>0.0</mean>
              <stddev>1.7e-2</stddev>
              <bias_mean>0.1</bias_mean>
              <bias_stddev>0.001</bias_stddev>
            </noise>
          </x>
          <y>
            <noise type="gaussian">
              <mean>0.0</mean>
              <stddev>1.7e-2</stddev>
              <bias_mean>0.1</bias_mean>
              <bias_stddev>0.001</bias_stddev>
            </noise>
          </y>
          <z>
            <noise type="gaussian">
              <mean>0.0</mean>
              <stddev>1.7e-2</stddev>
              <bias_mean>0.1</bias_mean>
              <bias_stddev>0.001</bias_stddev>
            </noise>
          </z>
        </linear_acceleration>
      </imu>
    </sensor>
  </gazebo>
  <!-- <xacro:property name="LEFT_WHEEL_KP" value="100"/>
  <xacro:property name="LEFT_WHEEL_KI" value="1"/>
  <xacro:property name="LEFT_WHEEL_KD" value="1"/>
  <xacro:property name="RIGHT_WHEEL_KP" value="100"/>
  <xacro:property name="RIGHT_WHEEL_KI" value="1"/>
  <xacro:property name="RIGHT_WHEEL_KD" value="1"/>
  <xacro:property name="LINEAR_VELOCITY_KP" value="100"/>
  <xacro:property name="LINEAR_VELOCITY_KI" value="1"/>
  <xacro:property name="LINEAR_VELOCITY_KD" value="1"/> -->
  <!-- <gazebo>
    <plugin name="gazebo_ros_ackermann_drive" filename="libgazebo_ros_ackermann_drive.so">
      <update_rate>50.0</update_rate>

  <front_left_joint>front_left_wheel_joint</front_left_joint>
  <front_right_joint>front_right_wheel_joint</front_right_joint>
  <rear_left_joint>left_rear_joint</rear_left_joint>
  <rear_right_joint>right_rear_joint</rear_right_joint>

  <left_steering_joint>front_left_wheel_joint</left_steering_joint>
  <right_steering_joint>front_right_wheel_joint</right_steering_joint>

  <max_steer>0.6458</max_steer>
  <max_steering_angle>7.85</max_steering_angle>
  <max_speed>20</max_speed>

  <left_steering_pid_gain>${LEFT_WHEEL_KP} ${LEFT_WHEEL_KI} ${LEFT_WHEEL_KD}</left_steering_pid_gain>
  <left_steering_i_range>0 0</left_steering_i_range>
  <right_steering_pid_gain>${RIGHT_WHEEL_KP} ${RIGHT_WHEEL_KI} ${RIGHT_WHEEL_KD}</right_steering_pid_gain>
  <right_steering_i_range>0 0</right_steering_i_range>
  <linear_velocity_pid_gain>${LINEAR_VELOCITY_KP} ${LINEAR_VELOCITY_KI} ${LINEAR_VELOCITY_KD}</linear_velocity_pid_gain>
  <linear_velocity_i_range>0 0</linear_velocity_i_range>

  <publish_odom>true</publish_odom>
  <publish_odom_tf>true</publish_odom_tf>
  <publish_wheel_tf>false</publish_wheel_tf>
  <publish_distance>true</publish_distance>

  <odometry_frame>odom</odometry_frame>
  <robot_base_frame>base_footprint</robot_base_frame>
</plugin>
</gazebo> -->
  <gazebo>
    <plugin filename="libgazebo_ros_p3d.so" name="ground_truth">
      <ros>
        <namespace>/odom</namespace>
        <remapping>odom:=ground_truth</remapping>
      </ros>
      <frame_name>map</frame_name>
      <body_name>base_footprint</body_name>
      <update_rate>100.0</update_rate>
    </plugin>
  </gazebo>
</robot>

